#VRML_SIM R2023b utf8

EXTERNPROTO "https://raw.githubusercontent.com/cyberbotics/webots/R2022b/projects/objects/backgrounds/protos/TexturedBackground.proto"
EXTERNPROTO "https://raw.githubusercontent.com/cyberbotics/webots/R2022b/projects/objects/backgrounds/protos/TexturedBackgroundLight.proto"
EXTERNPROTO "https://raw.githubusercontent.com/cyberbotics/webots/R2023b/projects/objects/apartment_structure/protos/Wall.proto"

WorldInfo {
  info [
    "A simple RCJ Soccer game simulated using Webots."
  ]
  title "RCJ Soccer Sim"
  optimalThreadCount 8
}
Viewpoint {
  orientation -0.5773502691896258 0.5773502691896258 0.5773502691896258 2.0944
  position 4.860628219838033e-06 3.911122624337006e-06 4.0844399251944585
}
TexturedBackground {
}
TexturedBackgroundLight {
}
DEF SOCCER_FIELD Solid {
  children [
    DEF GROUND Pose {
      rotation 0 0 1 1.5707996938995747
      children [
        Shape {
          appearance PBRAppearance {
            baseColorMap ImageTexture {
              url [
                "soccer/soccer-256.jpg"
              ]
            }
            roughness 1
            metalness 0
          }
          geometry Plane {
            size 1.5 1.5
          }
        }
      ]
    }
    DEF YELLOW_GOAL_GROUND Shape {
      appearance PBRAppearance {
        baseColorMap ImageTexture {
          url [
            "soccer/soccer-256.jpg"
          ]
        }
        roughness 1
        metalness 0
      }
      geometry IndexedFaceSet {
        coord Coordinate {
          point [
            -0.75 -0.95 0
            -0.75 -0.75 0
            0.75 -0.75 0
            0.75 -0.95 0
          ]
        }
        texCoord TextureCoordinate {
          point [
            0 0
            0 0
            0 0
            0 0
          ]
        }
        ccw FALSE
        coordIndex [
          0, 1, 2, 3
        ]
        texCoordIndex [
          0, 1, 2, 3
        ]
      }
    }
    DEF BLUE_GOAL_GROUND Shape {
      appearance PBRAppearance {
        baseColorMap ImageTexture {
          url [
            "soccer/soccer-256.jpg"
          ]
        }
        roughness 1
        metalness 0
      }
      geometry IndexedFaceSet {
        coord Coordinate {
          point [
            -0.75 0.95 0
            -0.75 0.75 0
            0.75 0.75 0
            0.75 0.95 0
          ]
        }
        texCoord TextureCoordinate {
          point [
            0 0
            0 0
            0 0
            0 0
          ]
        }
        coordIndex [
          0, 1, 2, 3
        ]
        texCoordIndex [
          0, 1, 2, 3
        ]
      }
    }
    DEF NORTH_WALL Shape {
      appearance DEF WALL_APPEARANCE PBRAppearance {
        baseColor 0.388235 0.388235 0.388235
        roughness 1
        metalness 0
      }
      geometry IndexedFaceSet {
        coord Coordinate {
          point [
            -0.66 -0.76 0
            -0.21 -0.76 0
            -0.21 -0.75 0
            -0.59 -0.75 0
            -0.65 -0.69 0
            -0.65 0.69 0
            -0.59 0.75 0
            -0.21 0.75 0
            -0.21 0.76 0
            -0.65 0.76 0
            -0.66 0.76 0
            -0.66 -0.76 0.09
            -0.21 -0.76 0.09
            -0.21 -0.75 0.09
            -0.59 -0.75 0.09
            -0.65 -0.69 0.09
            -0.65 0.69 0.09
            -0.59 0.75 0.09
            -0.21 0.75 0.09
            -0.21 0.76 0.09
            -0.65 0.76 0.09
            -0.66 0.76 0.09
          ]
        }
        coordIndex [
          0, 10, 9, -1, 9, 8, 7, -1, 9, 7, 6, -1, 2, 1, 0, -1, 3, 2, 0, -1, 9, 6, 5, -1, 4, 3, 0, -1, 0, 9, 5, -1, 0, 5, 4, -1, 11, 12, 13, -1, 11, 13, 14, -1, 20, 21, 11, -1, 18, 19, 20, -1, 17, 18, 20, -1, 11, 14, 15, -1, 16, 17, 20, -1, 11, 15, 16, -1, 11, 16, 20, -1, 0, 1, 12, 11, -1, 1, 2, 13, 12, -1, 2, 3, 14, 13, -1, 3, 4, 15, 14, -1, 4, 5, 16, 15, -1, 5, 6, 17, 16, -1, 6, 7, 18, 17, -1, 7, 8, 19, 18, -1, 8, 9, 20, 19, -1, 9, 10, 21, 20, -1, 10, 0, 11, 21, -1
        ]
      }
    }
    DEF SOUTH_WALL Shape {
      appearance USE WALL_APPEARANCE
      geometry IndexedFaceSet {
        coord Coordinate {
          point [
            0.66 -0.76 0
            0.66 0.76 0
            0.65 0.76 0
            0.21 0.76 0
            0.21 0.75 0
            0.59 0.75 0
            0.65 0.69 0
            0.65 -0.69 0
            0.59 -0.75 0
            0.21 -0.75 0
            0.21 -0.76 0
            0.66 -0.76 0.09
            0.66 0.76 0.09
            0.65 0.76 0.09
            0.21 0.76 0.09
            0.21 0.75 0.09
            0.59 0.75 0.09
            0.65 0.69 0.09
            0.65 -0.69 0.09
            0.59 -0.75 0.09
            0.21 -0.75 0.09
            0.21 -0.76 0.09
          ]
        }
        coordIndex [
          0, 10, 9, -1, 0, 9, 8, -1, 2, 1, 0, -1, 4, 3, 2, -1, 5, 4, 2, -1, 0, 8, 7, -1, 6, 5, 2, -1, 0, 7, 6, -1, 0, 6, 2, -1, 11, 12, 13, -1, 13, 14, 15, -1, 13, 15, 16, -1, 20, 21, 11, -1, 19, 20, 11, -1, 13, 16, 17, -1, 18, 19, 11, -1, 11, 13, 17, -1, 11, 17, 18, -1, 0, 1, 12, 11, -1, 1, 2, 13, 12, -1, 2, 3, 14, 13, -1, 3, 4, 15, 14, -1, 4, 5, 16, 15, -1, 5, 6, 17, 16, -1, 6, 7, 18, 17, -1, 7, 8, 19, 18, -1, 8, 9, 20, 19, -1, 9, 10, 21, 20, -1, 10, 0, 11, 21, -1
        ]
      }
    }
    DEF YELLOW_GOAL Shape {
      appearance PBRAppearance {
        baseColor 1 1 0
        roughness 1
        metalness 0
      }
      geometry IndexedFaceSet {
        coord Coordinate {
          point [
            -0.21 -0.86 0
            0.21 -0.86 0
            0.21 -0.75 0
            0.2 -0.75 0
            0.2 -0.85 0
            -0.2 -0.85 0
            -0.2 -0.75 0
            -0.21 -0.75 0
            -0.21 -0.86 0
            -0.21 -0.86 0.12
            0.21 -0.86 0.12
            0.21 -0.75 0.12
            0.2 -0.75 0.12
            0.2 -0.85 0.12
            -0.2 -0.85 0.12
            -0.2 -0.75 0.12
            -0.21 -0.75 0.12
            -0.21 -0.86 0.12
          ]
        }
        coordIndex [
          0, 1, 2, 3, 4, 5, 6, 7, 8, -1, 0, 1, 10, 9, -1, 1, 2, 11, 10, -1, 2, 3, 12, 11, -1, 3, 4, 13, 12, -1, 4, 5, 14, 13, -1, 5, 6, 15, 14, -1, 6, 7, 16, 15, -1, 7, 8, 17, 16, -1
        ]
      }
    }
    DEF BLUE_GOAL Shape {
      appearance PBRAppearance {
        baseColor 0 0 1
        roughness 1
        metalness 0
      }
      geometry IndexedFaceSet {
        coord Coordinate {
          point [
            -0.21 0.86 0
            -0.21 0.75 0
            -0.2 0.75 0
            -0.2 0.85 0
            0.2 0.85 0
            0.2 0.75 0
            0.21 0.75 0
            0.21 0.86 0
            -0.21 0.86 0
            -0.21 0.86 0.12
            -0.21 0.75 0.12
            -0.2 0.75 0.12
            -0.2 0.85 0.12
            0.2 0.85 0.12
            0.2 0.75 0.12
            0.21 0.75 0.12
            0.21 0.86 0.12
            -0.21 0.86 0.12
          ]
        }
        coordIndex [
          0, 1, 2, 3, 4, 5, 6, 7, 8, -1, 0, 1, 10, 9, -1, 1, 2, 11, 10, -1, 2, 3, 12, 11, -1, 3, 4, 13, 12, -1, 4, 5, 14, 13, -1, 5, 6, 15, 14, -1, 6, 7, 16, 15, -1, 7, 8, 17, 16, -1
        ]
      }
    }
  ]
  name "soccer field"
  boundingObject Group {
    children [
      USE GROUND
      DEF NOTH_BBOX Pose {
        translation 0.655 0 0.045
        children [
          Box {
            size 0.01 1.5 0.09
          }
        ]
      }
      DEF SOUTH_BBOX Pose {
        translation -0.655 0 0.045
        children [
          Box {
            size 0.01 1.5 0.09
          }
        ]
      }
      DEF NW_BBOX Pose {
        translation 0.43 0.755 0.045
        children [
          Box {
            size 0.435 0.01 0.09
          }
        ]
      }
      DEF NE_BBOX Pose {
        translation 0.43 -0.755 0.045
        children [
          Box {
            size 0.435 0.01 0.09
          }
        ]
      }
      DEF SW_BBOX Pose {
        translation -0.43 0.755 0.045
        children [
          Box {
            size 0.435 0.01 0.09
          }
        ]
      }
      DEF SE_BBOX Pose {
        translation -0.43 -0.755 0.045
        children [
          Box {
            size 0.435 0.01 0.09
          }
        ]
      }
      DEF NWC_BBOX Pose {
        translation -0.62 -0.725 0.045
        rotation 0 0 1 -0.7853
        children [
          Box {
            size 0.09 0.01 0.09
          }
        ]
      }
      DEF NEC_BBOX Pose {
        translation -0.62 0.725 0.045
        rotation 0 0 1 0.7853
        children [
          Box {
            size 0.09 0.01 0.09
          }
        ]
      }
      DEF SWC_BBOX Pose {
        translation 0.62 -0.725 0.045
        rotation 0 0 1 0.7853
        children [
          Box {
            size 0.09 0.01 0.09
          }
        ]
      }
      DEF SEC_BBOX Pose {
        translation 0.62 0.725 0.045
        rotation 0 0 1 -0.7853
        children [
          Box {
            size 0.09 0.01 0.09
          }
        ]
      }
      DEF YG_BBOX Pose {
        translation 0 0.855 0.061
        children [
          Box {
            size 0.42 0.01 0.12
          }
        ]
      }
      DEF BG_BBOX Pose {
        translation 0 -0.855 0.061
        children [
          Box {
            size 0.42 0.01 0.12
          }
        ]
      }
      DEF BGS_BBOX Pose {
        translation -0.205 -0.8 0.061
        children [
          Box {
            size 0.01 0.1 0.12
          }
        ]
      }
      DEF BGN_BBOX Pose {
        translation 0.205 -0.8 0.061
        children [
          Box {
            size 0.01 0.1 0.12
          }
        ]
      }
      DEF YGS_BBOX Pose {
        translation -0.205 0.8 0.061
        children [
          Box {
            size 0.01 0.1 0.12
          }
        ]
      }
      DEF YGN_BBOX Pose {
        translation 0.205 0.8 0.061
        children [
          Box {
            size 0.01 0.1 0.12
          }
        ]
      }
    ]
  }
  locked TRUE
}
DEF BALL Robot {
  translation 0.3 -0.4 0.015434929253089303
  rotation 0.5440387404558079 0.13060937506856687 0.8288323352931256 2.078205556282096
  children [
    DEF FOOTBALL_SHAPE Shape {
      appearance PBRAppearance {
        baseColorMap ImageTexture {
          url [
            "soccer/football_base_color.jpg"
          ]
        }
        roughness 0.4
        metalness 0
        normalMap ImageTexture {
          url [
            "soccer/football_normal.jpg"
          ]
        }
      }
      geometry Sphere {
        radius 0.021
        subdivision 3
      }
    }
    Emitter {
      name "ball emitter"
      type "infra-red"
      range 0.6
      channel 4
      baudRate 115200
      allowedChannels [
        4
      ]
    }
  ]
  name "soccer ball"
  model "soccer ball"
  boundingObject USE FOOTBALL_SHAPE
  physics Physics {
    density -1
    mass 0.05
  }
  recognitionColors [
    1 1 1
    0 0 0
  ]
  controller "rcj_soccer_ball"
  synchronization FALSE
  linearVelocity 0 0 0.04288494035708353
}
DEF B1 Robot {
  translation 0.5026550396282986 0.595280028640075 0.03748261696669538
  rotation 0.0008518296430643679 0.005389760976981946 -0.9999851123206135 1.537973885119618
  children [
    HingeJoint {
      jointParameters HingeJointParameters {
        position 757.4442010188324
        axis 0 1 0
        anchor 0 -0.045 -0.0176
      }
      device [
        RotationalMotor {
          name "left wheel motor"
        }
        PositionSensor {
          name "left wheel sensor"
        }
      ]
      endPoint Solid {
        translation 0 -0.045 -0.0176
        rotation 0.702538009020567 0.702535428459117 -0.1135091081860064 3.367642523665549
        children [
          Pose {
            rotation -0.5771969549958951 0.5776567755050862 -0.5771969549958951 2.0939354039397986
            children [
              DEF WHEEL_SHAPE Shape {
                appearance PBRAppearance {
                  roughness 1
                  metalness 0
                }
                geometry Cylinder {
                  height 0.01
                  radius 0.02
                }
              }
            ]
          }
        ]
        name "right wheel"
        boundingObject Pose {
          rotation -0.5771969549958951 0.5776567755050862 -0.5771969549958951 2.0939354039397986
          children [
            USE WHEEL_SHAPE
          ]
        }
        physics DEF WHEEL_PHYSICS Physics {
          density -1
          mass 0.005
        }
        linearVelocity -0.012629327219940308 -0.14261607109751537 -0.003202565880455777
        angularVelocity -0.07254363407563874 -0.04645987311950085 -0.08895145834359501
      }
    }
    HingeJoint {
      jointParameters HingeJointParameters {
        position 662.667380507883
        axis 0 1 0
        anchor 0 0.045 -0.0176
      }
      device [
        RotationalMotor {
          name "right wheel motor"
        }
        PositionSensor {
          name "right wheel sensor"
        }
      ]
      endPoint Solid {
        translation 0 0.045 -0.0176
        rotation -0.7051775012208523 -0.7051751268183983 -0.07384261837564217 3.2890098412120894
        children [
          Pose {
            rotation -0.5771969549958951 0.5776567755050862 -0.5771969549958951 2.0939354039397986
            children [
              Shape {
                appearance PBRAppearance {
                  roughness 1
                  metalness 0
                }
                geometry Cylinder {
                  height 0.01
                  radius 0.02
                }
              }
            ]
          }
        ]
        name "left wheel"
        boundingObject Pose {
          rotation -0.5771969549958951 0.5776567755050862 -0.5771969549958951 2.0939354039397986
          children [
            Shape {
              appearance PBRAppearance {
                roughness 1
                metalness 0
              }
              geometry Cylinder {
                height 0.01
                radius 0.02
              }
            }
          ]
        }
        physics USE WHEEL_PHYSICS
        linearVelocity -0.012961171511206487 -0.15042851938484575 0.0006961988826578057
        angularVelocity -0.0725435381415383 -0.046460920360051484 -0.08894729703957258
      }
    }
    DEF BLUE_ROBOT_SHAPE Shape {
      appearance PBRAppearance {
        baseColorMap ImageTexture {
          url [
            "soccer/blue.png"
          ]
        }
        roughness 1
        metalness 0
      }
      geometry Box {
        size 0.075 0.075 0.075
      }
    }
    Solid {
      translation 0 0.0385 0.02
      rotation 0 0 1 1.5707903061004251
      children [
        Shape {
          appearance PBRAppearance {
            baseColor 0 0 1
            roughness 1
            metalness 0
          }
          geometry Box {
            size 0.005 0.005 0.005
          }
        }
        DistanceSensor {
          name "distancesensor left"
          lookupTable [
            0 0 0
            1 1000 0.05
          ]
          type "sonar"
        }
      ]
      name "left sonar"
    }
    Solid {
      translation 0 -0.0385 0.02
      rotation 0 0 1 -1.5707996938995747
      children [
        Shape {
          appearance PBRAppearance {
            baseColor 0 0 1
            roughness 1
            metalness 0
          }
          geometry Box {
            size 0.005 0.005 0.005
          }
        }
        DistanceSensor {
          name "distancesensor right"
          lookupTable [
            0 0 0
            1 1000 0.05
          ]
          type "sonar"
        }
      ]
      name "right sonar"
    }
    Solid {
      translation 0.0385 0 0.02
      children [
        Shape {
          appearance PBRAppearance {
            baseColor 0 0 1
            roughness 1
            metalness 0
          }
          geometry Box {
            size 0.005 0.005 0.005
          }
        }
        DistanceSensor {
          name "distancesensor front"
          lookupTable [
            0 0 0
            1 1000 0.05
          ]
          type "sonar"
        }
      ]
      name "front sonar"
    }
    Solid {
      translation -0.0385 0 0.02
      rotation 0 0 1 3.141592653589793
      children [
        Shape {
          appearance PBRAppearance {
            baseColor 0 0 1
            roughness 1
            metalness 0
          }
          geometry Box {
            size 0.005 0.005 0.005
          }
        }
        DistanceSensor {
          name "distancesensor back"
          lookupTable [
            0 0 0
            1 1000 0.05
          ]
          type "sonar"
        }
      ]
      name "back sonar"
    }
    Receiver {
      name "supervisor receiver"
      channel 1
      allowedChannels [
        1
      ]
    }
    Receiver {
      name "team receiver"
      channel 2
      allowedChannels [
        2
      ]
    }
    Receiver {
      name "ball receiver"
      type "infra-red"
      channel 4
      allowedChannels [
        4
      ]
    }
    Emitter {
      name "team emitter"
      range 10
      channel 2
      baudRate 115200
      allowedChannels [
        2
      ]
    }
    GPS {
    }
    Compass {
    }
  ]
  name "B1"
  boundingObject USE BLUE_ROBOT_SHAPE
  physics DEF ROBOT_PHYSICS Physics {
    density -1
    mass 0.2
  }
  controller "rcj_soccer_team_blue"
  synchronization FALSE
  linearVelocity -0.013450264560685645 -0.14470150517450664 -0.0012081047119174037
  angularVelocity -0.07254361874117396 -0.046460958367016 -0.08895551981569967
}
DEF B2 Robot {
  translation 0.5590604913361801 0.7019186063951551 0.037002223802107465
  rotation -0.006630525163135398 -0.000998541029480585 -0.9999775192732452 1.5542365124594955
  children [
    HingeJoint {
      jointParameters HingeJointParameters {
        position 1893.5832454312047
        axis 0 1 0
        anchor 0 -0.045 -0.0176
      }
      device [
        RotationalMotor {
          name "left wheel motor"
        }
        PositionSensor {
          name "left wheel sensor"
        }
      ]
      endPoint Solid {
        translation 0 -0.045 -0.0176
        rotation -0.6777025441259706 -0.6777000547901042 -0.285380268103239 3.6975723610208986
        children [
          Pose {
            rotation -0.5771969549958951 0.5776567755050862 -0.5771969549958951 2.0939354039397986
            children [
              DEF WHEEL_SHAPE Shape {
                appearance PBRAppearance {
                  roughness 1
                  metalness 0
                }
                geometry Cylinder {
                  height 0.01
                  radius 0.02
                }
              }
            ]
          }
        ]
        name "right wheel"
        boundingObject Pose {
          rotation -0.5771969549958951 0.5776567755050862 -0.5771969549958951 2.0939354039397986
          children [
            USE WHEEL_SHAPE
          ]
        }
        physics DEF WHEEL_PHYSICS Physics {
          density -1
          mass 0.005
        }
        linearVelocity 0.090250954651065 0.06590123522422786 0.0029311847345558414
        angularVelocity 0.015764142309300493 -0.037827023565089664 0.003504111330051518
      }
    }
    HingeJoint {
      jointParameters HingeJointParameters {
        position 2359.3691158519946
        axis 0 1 0
        anchor 0 0.045 -0.0176
      }
      device [
        RotationalMotor {
          name "right wheel motor"
        }
        PositionSensor {
          name "right wheel sensor"
        }
      ]
      endPoint Solid {
        translation -7.227656784617657e-17 0.04499999999999993 -0.017599999999999998
        rotation -0.7070597437541074 -0.7070573630139619 0.011679219585174512 3.118235355034812
        children [
          Pose {
            rotation -0.5771969549958951 0.5776567755050862 -0.5771969549958951 2.0939354039397986
            children [
              Shape {
                appearance PBRAppearance {
                  roughness 1
                  metalness 0
                }
                geometry Cylinder {
                  height 0.01
                  radius 0.02
                }
              }
            ]
          }
        ]
        name "left wheel"
        boundingObject Pose {
          rotation -0.5771969549958951 0.5776567755050862 -0.5771969549958951 2.0939354039397986
          children [
            Shape {
              appearance PBRAppearance {
                roughness 1
                metalness 0
              }
              geometry Cylinder {
                height 0.01
                radius 0.02
              }
            }
          ]
        }
        physics USE WHEEL_PHYSICS
        linearVelocity 0.0901617775716284 0.06615934956544856 0.0063588165054209445
        angularVelocity 0.01576419236109934 -0.03782710166650202 0.003504116375009414
      }
    }
    DEF BLUE_ROBOT_SHAPE Shape {
      appearance PBRAppearance {
        baseColorMap ImageTexture {
          url [
            "soccer/blue.png"
          ]
        }
        roughness 1
        metalness 0
      }
      geometry Box {
        size 0.075 0.075 0.075
      }
    }
    Solid {
      translation 0 0.0385 0.02
      rotation 0 0 1 1.5707903061004251
      children [
        Shape {
          appearance PBRAppearance {
            baseColor 0 0 1
            roughness 1
            metalness 0
          }
          geometry Box {
            size 0.005 0.005 0.005
          }
        }
        DistanceSensor {
          name "distancesensor left"
          lookupTable [
            0 0 0
            1 1000 0.05
          ]
          type "sonar"
        }
      ]
      name "left sonar"
    }
    Solid {
      translation 0 -0.0385 0.02
      rotation 0 0 1 -1.5707996938995747
      children [
        Shape {
          appearance PBRAppearance {
            baseColor 0 0 1
            roughness 1
            metalness 0
          }
          geometry Box {
            size 0.005 0.005 0.005
          }
        }
        DistanceSensor {
          name "distancesensor right"
          lookupTable [
            0 0 0
            1 1000 0.05
          ]
          type "sonar"
        }
      ]
      name "right sonar"
    }
    Solid {
      translation 0.0385 0 0.02
      children [
        Shape {
          appearance PBRAppearance {
            baseColor 0 0 1
            roughness 1
            metalness 0
          }
          geometry Box {
            size 0.005 0.005 0.005
          }
        }
        DistanceSensor {
          name "distancesensor front"
          lookupTable [
            0 0 0
            1 1000 0.05
          ]
          type "sonar"
        }
      ]
      name "front sonar"
    }
    Solid {
      translation -0.0385 0 0.02
      rotation 0 0 1 3.141592653589793
      children [
        Shape {
          appearance PBRAppearance {
            baseColor 0 0 1
            roughness 1
            metalness 0
          }
          geometry Box {
            size 0.005 0.005 0.005
          }
        }
        DistanceSensor {
          name "distancesensor back"
          lookupTable [
            0 0 0
            1 1000 0.05
          ]
          type "sonar"
        }
      ]
      name "back sonar"
    }
    Receiver {
      name "supervisor receiver"
      channel 1
      allowedChannels [
        1
      ]
    }
    Receiver {
      name "team receiver"
      channel 2
      allowedChannels [
        2
      ]
    }
    Receiver {
      name "ball receiver"
      type "infra-red"
      channel 4
      allowedChannels [
        4
      ]
    }
    Emitter {
      name "team emitter"
      range 10
      channel 2
      baudRate 115200
      allowedChannels [
        2
      ]
    }
    GPS {
    }
    Compass {
    }
  ]
  name "B2"
  boundingObject USE BLUE_ROBOT_SHAPE
  physics USE ROBOT_PHYSICS
  controller "rcj_soccer_team_blue"
  synchronization FALSE
  linearVelocity 0.08954373943440083 0.06575642599645093 0.004625061048380762
  angularVelocity 0.015764344890195202 -0.03782713528301964 0.0035041063452106724
}
DEF B3 Robot {
  translation 0.48072484740336646 0.6620465477623122 0.037634882930667024
  rotation -0.006308210483291378 -0.008196600610891763 -0.9999465096788549 1.5508462121373003
  children [
    HingeJoint {
      jointParameters HingeJointParameters {
        position 295.85591120179856
        axis 0 1 0
        anchor 0 -0.045 -0.0176
      }
      device [
        RotationalMotor {
          name "left wheel motor"
        }
        PositionSensor {
          name "left wheel sensor"
        }
      ]
      endPoint Solid {
        translation 0 -0.045 -0.0176
        rotation -0.26041276165973015 -0.26041180511200385 -0.9297154862231028 4.639573071065529
        children [
          Pose {
            rotation -0.5771969549958951 0.5776567755050862 -0.5771969549958951 2.0939354039397986
            children [
              DEF WHEEL_SHAPE Shape {
                appearance PBRAppearance {
                  roughness 1
                  metalness 0
                }
                geometry Cylinder {
                  height 0.01
                  radius 0.02
                }
              }
            ]
          }
        ]
        name "right wheel"
        boundingObject Pose {
          rotation -0.5771969549958951 0.5776567755050862 -0.5771969549958951 2.0939354039397986
          children [
            USE WHEEL_SHAPE
          ]
        }
        physics DEF WHEEL_PHYSICS Physics {
          density -1
          mass 0.005
        }
        linearVelocity -0.006708377472385885 -0.0014096127284274704 -0.002839807231701275
        angularVelocity 0.07149461073892766 -0.07058640108324912 -0.002840609024593349
      }
    }
    HingeJoint {
      jointParameters HingeJointParameters {
        position 913.7646793035115
        axis 0 1 0
        anchor 0 0.045 -0.0176
      }
      device [
        RotationalMotor {
          name "right wheel motor"
        }
        PositionSensor {
          name "right wheel sensor"
        }
      ]
      endPoint Solid {
        translation 0 0.045 -0.0176
        rotation -0.6984790926201058 -0.6984767407718692 -0.15574723038725433 3.4506034632522873
        children [
          Pose {
            rotation -0.5771969549958951 0.5776567755050862 -0.5771969549958951 2.0939354039397986
            children [
              Shape {
                appearance PBRAppearance {
                  roughness 1
                  metalness 0
                }
                geometry Cylinder {
                  height 0.01
                  radius 0.02
                }
              }
            ]
          }
        ]
        name "left wheel"
        boundingObject Pose {
          rotation -0.5771969549958951 0.5776567755050862 -0.5771969549958951 2.0939354039397986
          children [
            Shape {
              appearance PBRAppearance {
                roughness 1
                metalness 0
              }
              geometry Cylinder {
                height 0.01
                radius 0.02
              }
            }
          ]
        }
        physics USE WHEEL_PHYSICS
        linearVelocity -0.0038234503765889744 -0.0015752528323784657 0.0028496193848425388
        angularVelocity 0.07150071174575451 -0.07058634308944017 -0.0028398995575752706
      }
    }
    DEF BLUE_ROBOT_SHAPE Shape {
      appearance PBRAppearance {
        baseColorMap ImageTexture {
          url [
            "soccer/blue.png"
          ]
        }
        roughness 1
        metalness 0
      }
      geometry Box {
        size 0.075 0.075 0.075
      }
    }
    Solid {
      translation 0 0.0385 0.02
      rotation 0 0 1 1.5707903061004251
      children [
        Shape {
          appearance PBRAppearance {
            baseColor 0 0 1
            roughness 1
            metalness 0
          }
          geometry Box {
            size 0.005 0.005 0.005
          }
        }
        DistanceSensor {
          name "distancesensor left"
          lookupTable [
            0 0 0
            1 1000 0.05
          ]
          type "sonar"
        }
      ]
      name "left sonar"
    }
    Solid {
      translation 0 -0.0385 0.02
      rotation 0 0 1 -1.5707996938995747
      children [
        Shape {
          appearance PBRAppearance {
            baseColor 0 0 1
            roughness 1
            metalness 0
          }
          geometry Box {
            size 0.005 0.005 0.005
          }
        }
        DistanceSensor {
          name "distancesensor right"
          lookupTable [
            0 0 0
            1 1000 0.05
          ]
          type "sonar"
        }
      ]
      name "right sonar"
    }
    Solid {
      translation 0.0385 0 0.02
      children [
        Shape {
          appearance PBRAppearance {
            baseColor 0 0 1
            roughness 1
            metalness 0
          }
          geometry Box {
            size 0.005 0.005 0.005
          }
        }
        DistanceSensor {
          name "distancesensor front"
          lookupTable [
            0 0 0
            1 1000 0.05
          ]
          type "sonar"
        }
      ]
      name "front sonar"
    }
    Solid {
      translation -0.0385 0 0.02
      rotation 0 0 1 3.141592653589793
      children [
        Shape {
          appearance PBRAppearance {
            baseColor 0 0 1
            roughness 1
            metalness 0
          }
          geometry Box {
            size 0.005 0.005 0.005
          }
        }
        DistanceSensor {
          name "distancesensor back"
          lookupTable [
            0 0 0
            1 1000 0.05
          ]
          type "sonar"
        }
      ]
      name "back sonar"
    }
    Receiver {
      name "supervisor receiver"
      channel 1
      allowedChannels [
        1
      ]
    }
    Receiver {
      name "team receiver"
      channel 2
      allowedChannels [
        2
      ]
    }
    Receiver {
      name "ball receiver"
      type "infra-red"
      channel 4
      allowedChannels [
        4
      ]
    }
    Emitter {
      name "team emitter"
      range 10
      channel 2
      baudRate 115200
      allowedChannels [
        2
      ]
    }
    GPS {
    }
    Compass {
    }
  ]
  name "B3"
  boundingObject USE BLUE_ROBOT_SHAPE
  physics USE ROBOT_PHYSICS
  controller "rcj_soccer_team_blue"
  synchronization FALSE
  linearVelocity -0.007995122786728131 -0.002817918778096819 0.0003964912354908554
  angularVelocity 0.0714946131899979 -0.0705865233205557 -0.0028406209334170263
}
DEF Y1 Robot {
  translation -0.0230554302795311 -0.45142074127023457 0.04599728477856794
  rotation -0.14216374285949832 0.13377056275878274 0.9807624109616849 1.585838775938211
  children [
    HingeJoint {
      jointParameters HingeJointParameters {
        position -300.79344507931216
        axis 0 1 0
        anchor 0 -0.045 -0.0176
      }
      device [
        RotationalMotor {
          name "left wheel motor"
        }
        PositionSensor {
          name "left wheel sensor"
        }
      ]
      endPoint Solid {
        translation 5.106691521211334e-16 -0.04499999999999968 -0.017600000000000525
        rotation -0.36266984078547493 0.3626685086272173 -0.8584533414430561 1.7228338068769846
        children [
          Pose {
            rotation -0.5771969549958951 0.5776567755050862 -0.5771969549958951 2.0939354039397986
            children [
              DEF WHEEL_SHAPE Shape {
                appearance PBRAppearance {
                  roughness 1
                  metalness 0
                }
                geometry Cylinder {
                  height 0.01
                  radius 0.02
                }
              }
            ]
          }
        ]
        name "right wheel"
        boundingObject Pose {
          rotation -0.5771969549958951 0.5776567755050862 -0.5771969549958951 2.0939354039397986
          children [
            USE WHEEL_SHAPE
          ]
        }
        physics DEF WHEEL_PHYSICS Physics {
          density -1
          mass 0.005
        }
        linearVelocity 0.0026621121404882863 -0.09025249123072542 -0.07575395715323457
        angularVelocity -7.151362389207449 0.09335818201816101 -0.06758211197728224
      }
    }
    HingeJoint {
      jointParameters HingeJointParameters {
        position -489.03974435785744
        axis 0 1 0
        anchor 0 0.045 -0.0176
      }
      device [
        RotationalMotor {
          name "right wheel motor"
        }
        PositionSensor {
          name "right wheel sensor"
        }
      ]
      endPoint Solid {
        translation -2.779196952164064e-16 0.04500000000000001 -0.01759999999999952
        rotation -0.4476821308884187 0.447680486463161 -0.7740561295689818 1.8241559893063066
        children [
          Pose {
            rotation -0.5771969549958951 0.5776567755050862 -0.5771969549958951 2.0939354039397986
            children [
              Shape {
                appearance PBRAppearance {
                  roughness 1
                  metalness 0
                }
                geometry Cylinder {
                  height 0.01
                  radius 0.02
                }
              }
            ]
          }
        ]
        name "left wheel"
        boundingObject Pose {
          rotation -0.5771969549958951 0.5776567755050862 -0.5771969549958951 2.0939354039397986
          children [
            Shape {
              appearance PBRAppearance {
                roughness 1
                metalness 0
              }
              geometry Cylinder {
                height 0.01
                radius 0.02
              }
            }
          ]
        }
        physics USE WHEEL_PHYSICS
        linearVelocity 0.0028204478896671943 -0.09164535077796043 -0.069581662700856
        angularVelocity 12.847664285486116 0.0401965449314101 0.12529084125604573
      }
    }
    DEF YELLOW_ROBOT_SHAPE Shape {
      appearance PBRAppearance {
        baseColorMap ImageTexture {
          url [
            "soccer/Y1.png"
          ]
        }
        roughness 1
        metalness 0
      }
      geometry Box {
        size 0.075 0.075 0.075
      }
    }
    Solid {
      translation 0 0.0385 0.02
      rotation 0 0 1 1.5708
      children [
        Shape {
          appearance PBRAppearance {
            baseColor 1 1 0
            roughness 1
            metalness 0
          }
          geometry Box {
            size 0.005 0.005 0.005
          }
        }
        DistanceSensor {
          name "distancesensor left"
          lookupTable [
            0 0 0
            1 1000 0.05
          ]
          type "sonar"
        }
      ]
      name "left sonar"
    }
    Solid {
      translation 0 -0.0385 0.02
      rotation 0 0 1 -1.5707996938995747
      children [
        Shape {
          appearance PBRAppearance {
            baseColor 1 1 0
            roughness 1
            metalness 0
          }
          geometry Box {
            size 0.005 0.005 0.005
          }
        }
        DistanceSensor {
          name "distancesensor right"
          lookupTable [
            0 0 0
            1 1000 0.05
          ]
          type "sonar"
        }
      ]
      name "right sonar"
    }
    Solid {
      translation 0.0385 0 0.02
      children [
        Shape {
          appearance PBRAppearance {
            baseColor 1 1 0
            roughness 1
            metalness 0
          }
          geometry Box {
            size 0.005 0.005 0.005
          }
        }
        DistanceSensor {
          name "distancesensor front"
          lookupTable [
            0 0 0
            1 1000 0.05
          ]
          type "sonar"
        }
      ]
      name "front sonar"
    }
    Solid {
      translation -0.0385 0 0.02
      rotation 0 0 1 3.141592653589793
      children [
        Shape {
          appearance PBRAppearance {
            baseColor 1 1 0
            roughness 1
            metalness 0
          }
          geometry Box {
            size 0.005 0.005 0.005
          }
        }
        DistanceSensor {
          name "distancesensor back"
          lookupTable [
            0 0 0
            1 1000 0.05
          ]
          type "sonar"
        }
      ]
      name "back sonar"
    }
    Receiver {
      name "supervisor receiver"
      channel 1
      allowedChannels [
        1
      ]
    }
    Receiver {
      name "team receiver"
      channel 3
      allowedChannels [
        3
      ]
    }
    Receiver {
      name "ball receiver"
      type "infra-red"
      channel 4
      allowedChannels [
        4
      ]
    }
    Emitter {
      name "team emitter"
      range 10
      channel 3
      baudRate 115200
      allowedChannels [
        3
      ]
    }
    GPS {
    }
    Compass {
    }
  ]
  name "Y1"
  boundingObject USE YELLOW_ROBOT_SHAPE
  physics USE ROBOT_PHYSICS
  controller "rcj_soccer_team_yellow"
  synchronization FALSE
  linearVelocity 0.003634178362685445 -0.138203805149137 -0.05755544620342474
  angularVelocity 2.8480962632823057 0.06036873194122559 0.03189303260719646
}
DEF Y2 Robot {
  translation 0.5724684581098254 0.5463145975398652 0.038521893841041724
  rotation 0.04122729667186815 -0.03263246957085357 0.9986167592919902 1.610848936882232
  children [
    HingeJoint {
      jointParameters HingeJointParameters {
        position 947.7293520684244
        axis 0 1 0
        anchor 0 -0.045 -0.0176
      }
      device [
        RotationalMotor {
          name "left wheel motor"
        }
        PositionSensor {
          name "left wheel sensor"
        }
      ]
      endPoint Solid {
        translation 2.262581431153147e-16 -0.045000000000000095 -0.017599999999999623
        rotation -0.44235988423925543 0.44235825936366835 0.7801518462380115 4.466630481025122
        children [
          Pose {
            rotation -0.5771969549958951 0.5776567755050862 -0.5771969549958951 2.0939354039397986
            children [
              DEF WHEEL_SHAPE Shape {
                appearance PBRAppearance {
                  roughness 1
                  metalness 0
                }
                geometry Cylinder {
                  height 0.01
                  radius 0.02
                }
              }
            ]
          }
        ]
        name "right wheel"
        boundingObject Pose {
          rotation -0.5771969549958951 0.5776567755050862 -0.5771969549958951 2.0939354039397986
          children [
            USE WHEEL_SHAPE
          ]
        }
        physics DEF WHEEL_PHYSICS Physics {
          density -1
          mass 0.005
        }
        linearVelocity 0.03915119775850875 -0.2183634924306783 0.03342370024608992
        angularVelocity -0.8994159292050785 0.0035384672455104488 -0.1748937271498341
      }
    }
    HingeJoint {
      jointParameters HingeJointParameters {
        position 1592.3980365965028
        axis 0 1 0
        anchor 0 0.045 -0.0176
      }
      device [
        RotationalMotor {
          name "right wheel motor"
        }
        PositionSensor {
          name "right wheel sensor"
        }
      ]
      endPoint Solid {
        translation 6.172285817891008e-16 0.04499999999999971 -0.017599999999999748
        rotation 0.7003309946715882 -0.7003284222169405 0.13811806159020093 3.4160910679434004
        children [
          Pose {
            rotation -0.5771969549958951 0.5776567755050862 -0.5771969549958951 2.0939354039397986
            children [
              Shape {
                appearance PBRAppearance {
                  roughness 1
                  metalness 0
                }
                geometry Cylinder {
                  height 0.01
                  radius 0.02
                }
              }
            ]
          }
        ]
        name "left wheel"
        boundingObject Pose {
          rotation -0.5771969549958951 0.5776567755050862 -0.5771969549958951 2.0939354039397986
          children [
            Shape {
              appearance PBRAppearance {
                roughness 1
                metalness 0
              }
              geometry Cylinder {
                height 0.01
                radius 0.02
              }
            }
          ]
        }
        physics USE WHEEL_PHYSICS
        linearVelocity 0.03863763958703235 -0.20175732251803954 0.03713292998591908
        angularVelocity -0.8994161304829102 0.003538368032108788 -0.1748936651449525
      }
    }
    DEF YELLOW_ROBOT_SHAPE Shape {
      appearance PBRAppearance {
        baseColorMap ImageTexture {
          url [
            "soccer/Y2.png"
          ]
        }
        roughness 1
        metalness 0
      }
      geometry Box {
        size 0.075 0.075 0.075
      }
    }
    Solid {
      translation 0 0.0385 0.02
      rotation 0 0 1 1.5708
      children [
        Shape {
          appearance PBRAppearance {
            baseColor 1 1 0
            roughness 1
            metalness 0
          }
          geometry Box {
            size 0.005 0.005 0.005
          }
        }
        DistanceSensor {
          name "distancesensor left"
          lookupTable [
            0 0 0
            1 1000 0.05
          ]
          type "sonar"
        }
      ]
      name "left sonar"
    }
    Solid {
      translation 0 -0.0385 0.02
      rotation 0 0 1 -1.5707996938995747
      children [
        Shape {
          appearance PBRAppearance {
            baseColor 1 1 0
            roughness 1
            metalness 0
          }
          geometry Box {
            size 0.005 0.005 0.005
          }
        }
        DistanceSensor {
          name "distancesensor right"
          lookupTable [
            0 0 0
            1 1000 0.05
          ]
          type "sonar"
        }
      ]
      name "right sonar"
    }
    Solid {
      translation 0.0385 0 0.02
      children [
        Shape {
          appearance PBRAppearance {
            baseColor 1 1 0
            roughness 1
            metalness 0
          }
          geometry Box {
            size 0.005 0.005 0.005
          }
        }
        DistanceSensor {
          name "distancesensor front"
          lookupTable [
            0 0 0
            1 1000 0.05
          ]
          type "sonar"
        }
      ]
      name "front sonar"
    }
    Solid {
      translation -0.0385 0 0.02
      rotation 0 0 1 3.141592653589793
      children [
        Shape {
          appearance PBRAppearance {
            baseColor 1 1 0
            roughness 1
            metalness 0
          }
          geometry Box {
            size 0.005 0.005 0.005
          }
        }
        DistanceSensor {
          name "distancesensor back"
          lookupTable [
            0 0 0
            1 1000 0.05
          ]
          type "sonar"
        }
      ]
      name "back sonar"
    }
    Receiver {
      name "supervisor receiver"
      channel 1
      allowedChannels [
        1
      ]
    }
    Receiver {
      name "team receiver"
      channel 3
      allowedChannels [
        3
      ]
    }
    Receiver {
      name "ball receiver"
      type "infra-red"
      channel 4
      allowedChannels [
        4
      ]
    }
    Emitter {
      name "team emitter"
      range 10
      channel 3
      baudRate 115200
      allowedChannels [
        3
      ]
    }
    GPS {
    }
    Compass {
    }
  ]
  name "Y2"
  boundingObject USE YELLOW_ROBOT_SHAPE
  physics USE ROBOT_PHYSICS
  controller "rcj_soccer_team_yellow"
  synchronization FALSE
  linearVelocity 0.03866939294559839 -0.19431799919623452 0.03573642591348292
  angularVelocity -0.8994161156321372 0.0035383917406617282 -0.17489371879099624
}
DEF Y3 Robot {
  translation 0.49679777927455826 0.6519812229150012 0.03787570231352204
  rotation -0.004688493118062465 0.00943809720640438 0.9999444686348359 1.588858720191157
  children [
    HingeJoint {
      jointParameters HingeJointParameters {
        position 3484.677057565476
        axis 0 1 0
        anchor 0 -0.045 -0.0176
      }
      device [
        RotationalMotor {
          name "left wheel motor"
        }
        PositionSensor {
          name "left wheel sensor"
        }
      ]
      endPoint Solid {
        translation -5.4671178886522123e-17 -0.04500000000000001 -0.01759999999999996
        rotation -0.6878046581220874 0.6878021316791698 0.23206244832619666 3.5976436954614988
        children [
          Pose {
            rotation -0.5771969549958951 0.5776567755050862 -0.5771969549958951 2.0939354039397986
            children [
              DEF WHEEL_SHAPE Shape {
                appearance PBRAppearance {
                  roughness 1
                  metalness 0
                }
                geometry Cylinder {
                  height 0.01
                  radius 0.02
                }
              }
            ]
          }
        ]
        name "right wheel"
        boundingObject Pose {
          rotation -0.5771969549958951 0.5776567755050862 -0.5771969549958951 2.0939354039397986
          children [
            USE WHEEL_SHAPE
          ]
        }
        physics DEF WHEEL_PHYSICS Physics {
          density -1
          mass 0.005
        }
        linearVelocity -0.0007599579339464331 -0.0008166871798943355 0.0027294756722377744
        angularVelocity 0.07231226539032312 -0.03768636918836842 -0.0014240256406611584
      }
    }
    HingeJoint {
      jointParameters HingeJointParameters {
        position 4306.625373824341
        axis 0 1 0
        anchor 0 0.045 -0.0176
      }
      device [
        RotationalMotor {
          name "right wheel motor"
        }
        PositionSensor {
          name "right wheel sensor"
        }
      ]
      endPoint Solid {
        translation 1.4032643057856216e-16 0.04499999999999988 -0.017599999999999925
        rotation 0.6959410367136076 -0.6959384803841483 0.17701893949120656 3.4919992713881154
        children [
          Pose {
            rotation -0.5771969549958951 0.5776567755050862 -0.5771969549958951 2.0939354039397986
            children [
              Shape {
                appearance PBRAppearance {
                  roughness 1
                  metalness 0
                }
                geometry Cylinder {
                  height 0.01
                  radius 0.02
                }
              }
            ]
          }
        ]
        name "left wheel"
        boundingObject Pose {
          rotation -0.5771969549958951 0.5776567755050862 -0.5771969549958951 2.0939354039397986
          children [
            Shape {
              appearance PBRAppearance {
                roughness 1
                metalness 0
              }
              geometry Cylinder {
                height 0.01
                radius 0.02
              }
            }
          ]
        }
        physics USE WHEEL_PHYSICS
        linearVelocity -0.003464885807807146 -0.0014091659933818355 -0.0023229607050414213
        angularVelocity 0.0723072105956107 -0.037690440340667763 -0.0014219462239955238
      }
    }
    DEF YELLOW_ROBOT_SHAPE Shape {
      appearance PBRAppearance {
        baseColorMap ImageTexture {
          url [
            "soccer/Y3.png"
          ]
        }
        roughness 1
        metalness 0
      }
      geometry Box {
        size 0.075 0.075 0.075
      }
    }
    Solid {
      translation 0 0.0385 0.02
      rotation 0 0 1 1.5708
      children [
        Shape {
          appearance PBRAppearance {
            baseColor 1 1 0
            roughness 1
            metalness 0
          }
          geometry Box {
            size 0.005 0.005 0.005
          }
        }
        DistanceSensor {
          name "distancesensor left"
          lookupTable [
            0 0 0
            1 1000 0.05
          ]
          type "sonar"
        }
      ]
      name "left sonar"
    }
    Solid {
      translation 0 -0.0385 0.02
      rotation 0 0 1 -1.5707996938995747
      children [
        Shape {
          appearance PBRAppearance {
            baseColor 1 1 0
            roughness 1
            metalness 0
          }
          geometry Box {
            size 0.005 0.005 0.005
          }
        }
        DistanceSensor {
          name "distancesensor right"
          lookupTable [
            0 0 0
            1 1000 0.05
          ]
          type "sonar"
        }
      ]
      name "right sonar"
    }
    Solid {
      translation 0.0385 0 0.02
      children [
        Shape {
          appearance PBRAppearance {
            baseColor 1 1 0
            roughness 1
            metalness 0
          }
          geometry Box {
            size 0.005 0.005 0.005
          }
        }
        DistanceSensor {
          name "distancesensor front"
          lookupTable [
            0 0 0
            1 1000 0.05
          ]
          type "sonar"
        }
      ]
      name "front sonar"
    }
    Solid {
      translation -0.0385 0 0.02
      rotation 0 0 1 3.141592653589793
      children [
        Shape {
          appearance PBRAppearance {
            baseColor 1 1 0
            roughness 1
            metalness 0
          }
          geometry Box {
            size 0.005 0.005 0.005
          }
        }
        DistanceSensor {
          name "distancesensor back"
          lookupTable [
            0 0 0
            1 1000 0.05
          ]
          type "sonar"
        }
      ]
      name "back sonar"
    }
    Receiver {
      name "supervisor receiver"
      channel 1
      allowedChannels [
        1
      ]
    }
    Receiver {
      name "team receiver"
      channel 3
      allowedChannels [
        3
      ]
    }
    Receiver {
      name "ball receiver"
      type "infra-red"
      channel 4
      allowedChannels [
        4
      ]
    }
    Emitter {
      name "team emitter"
      range 10
      channel 3
      baudRate 115200
      allowedChannels [
        3
      ]
    }
    GPS {
    }
    Compass {
    }
  ]
  name "Y3"
  boundingObject USE YELLOW_ROBOT_SHAPE
  physics USE ROBOT_PHYSICS
  controller "rcj_soccer_team_yellow"
  synchronization FALSE
  linearVelocity -0.001484787281628949 -0.0027970380214325857 0.0010003278626023859
  angularVelocity 0.0723126246763361 -0.037685852503570254 -0.0014288512927704278
}
Robot {
  children [
    Emitter {
      range 10
      channel 1
      baudRate 115200
      allowedChannels [
        1
      ]
    }
  ]
  controller "rcj_soccer_referee_supervisor"
  supervisor TRUE
}
Wall {
  translation -0.15 -0.25 -0.06
  size 1 0.05 0.15
}
Wall {
  translation 0.15 0.25 -0.06
  name "wall(1)"
  size 1 0.05 0.15
}
Wall {
  translation 0.23 0.5 -0.06
  rotation 0 0 1 1.5708
  name "wall(3)"
  size 0.5 0.05 0.15
}
